Workbook
Name Slicer_Attrition: #N/A
Name Slicer_Department: #N/A
Name Slicer_Gender: #N/A

Sheet HR_Data
A1: Employee ID | B1: Age | C1: Gender | D1: Department | E1: Job Role | F1: Monthly Income | G1: Years At Company | H1: Performance Rating | I1: Attrition | J1: Experience Level
A2: 1001 | B2: 37 | C2: Female | D2: IT | E2: Engineer | F2: 106935 | G2: 2 | H2: 5 | I2: No | J2: =IF(G2<3,"Junior",IF(G2<7,"Mid-Level","Senior")) -> Junior
A3: 1002 | B3: 32 | C3: Female | D3: Finance | E3: Accountant | F3: 92802 | G3: 2 | H3: 1 | I3: No | J3: =IF(G3<3,"Junior",IF(G3<7,"Mid-Level","Senior")) -> Junior
A4: 1003 | B4: 28 | C4: Male | D4: Finance | E4: Accountant | F4: 20173 | G4: 19 | H4: 4 | I4: No | J4: =IF(G4<3,"Junior",IF(G4<7,"Mid-Level","Senior")) -> Senior
A5: 1004 | B5: 55 | C5: Male | D5: Sales | E5: Sales Executive | F5: 100197 | G5: 1 | H5: 3 | I5: No | J5: =IF(G5<3,"Junior",IF(G5<7,"Mid-Level","Senior")) -> Junior
A6: 1005 | B6: 34 | C6: Male | D6: Finance | E6: Financial Analyst | F6: 65942 | G6: 17 | H6: 1 | I6: No | J6: =IF(G6<3,"Junior",IF(G6<7,"Mid-Level","Senior")) -> Senior
A7: 1006 | B7: 54 | C7: Female | D7: IT | E7: Engineer | F7: 69383 | G7: 2 | H7: 3 | I7: No | J7: =IF(G7<3,"Junior",IF(G7<7,"Mid-Level","Senior")) -> Junior
A8: 1007 | B8: 23 | C8: Male | D8: Sales | E8: Sales Executive | F8: 58398 | G8: 1 | H8: 4 | I8: No | J8: =IF(G8<3,"Junior",IF(G8<7,"Mid-Level","Senior")) -> Junior
A9: 1008 | B9: 47 | C9: Female | D9: Finance | E9: Financial Analyst | F9: 77216 | G9: 10 | H9: 1 | I9: No | J9: =IF(G9<3,"Junior",IF(G9<7,"Mid-Level","Senior")) -> Senior
A10: 1009 | B10: 51 | C10: Male | D10: Sales | E10: Sales Manager | F10: 31583 | G10: 13 | H10: 5 | I10: Yes | J10: =IF(G10<3,"Junior",IF(G10<7,"Mid-Level","Senior")) -> Senior
A11: 1010 | B11: 54 | C11: Female | D11: Finance | E11: Financial Analyst | F11: 117177 | G11: 2 | H11: 1 | I11: No | J11: =IF(G11<3,"Junior",IF(G11<7,"Mid-Level","Senior")) -> Junior
A12: 1011 | B12: 45 | C12: Male | D12: HR | E12: HR Executive | F12: 76243 | G12: 13 | H12: 3 | I12: No | J12: =IF(G12<3,"Junior",IF(G12<7,"Mid-Level","Senior")) -> Senior
A13: 1012 | B13: 40 | C13: Male | D13: Operations | E13: Supervisor | F13: 43813 | G13: 4 | H13: 2 | I13: No | J13: =IF(G13<3,"Junior",IF(G13<7,"Mid-Level","Senior")) -> Mid-Level
... A1001: 2000 | B1001: 58 | C1001: Female | D1001: HR | E1001: Recruiter | F1001: 25029 | G1001: 4 | H1001: 2 | I1001: No | J1001: =IF(G1001<3,"Junior",IF(G1001<7,"Mid-Level","Senior")) -> Mid-Level

Sheet KPI
A1: Metrics | B1: Value
A3: Total Employees | B3: =COUNTA(HR_Data!A:A)-1 -> 1000
A4: Employees Stayed | B4: =COUNTIF(HR_Data!I:I,"No") -> 811
A5: Employees Left | B5: =COUNTIF(HR_Data!I:I,"Yes") -> 189
A6: Attrition Rate | B6: =COUNTIF(HR_Data!I:I,"Yes")/(COUNTA(HR_Data!A:A)-1) -> 0.189
A7: Avg Salary | B7: =AVERAGE(HR_Data!F:F) -> 70959.332
A8: Avg Experience | B8: =AVERAGE(HR_Data!G:G) -> 10.06
A9: Avg Performance | B9: =AVERAGE(HR_Data!H:H) -> 3.033

Sheet HR Analytics Dashboard

Sheet Pivots
B2: Employees by Department
B4: Row Labels | C4: Count of Employee ID
B5: Finance | C5: 188
B6: Marketing | C6: 171
B7: IT | C7: 169
B8: HR | C8: 164
B9: Operations | C9: 155
B10: Sales | C10: 153
B11: Grand Total | C11: 1000
B16: Gender Distribution
B18: Row Labels | C18: Count of Employee ID
B19: Female | C19: 0.504
B20: Male | C20: 0.496
B21: Grand Total | C21: 1
B26: Attrition by Department
B28: Count of Employee ID | C28: Column Labels
B29: Row Labels | C29: No | D29: Yes | E29: Grand Total
B30: Finance | C30: 148 | D30: 40 | E30: 188
B31: HR | C31: 132 | D31: 32 | E31: 164
B32: IT | C32: 141 | D32: 28 | E32: 169
B33: Marketing | C33: 139 | D33: 32 | E33: 171
B34: Operations | C34: 123 | D34: 32 | E34: 155
B35: Sales | C35: 128 | D35: 25 | E35: 153
B36: Grand Total | C36: 811 | D36: 189 | E36: 1000
B41: Average Salary by Department
A42: *
B44: Row Labels | C44: Average of Monthly Income
B45: Finance | C45: 71362.601
B46: HR | C46: 69598.585
B47: IT | C47: 72111.805
B48: Marketing | C48: 71612.55
B49: Operations | C49: 69317.994
B50: Sales | C50: 71582.124
B51: Grand Total | C51: 70959.332
B57: Average Performance Rating by Department
B59: Row Labels | C59: Average of Performance Rating
B60: Finance | C60: 2.9787234
B61: HR | C61: 3.1585366
B62: IT | C62: 3.0414201
B63: Marketing | C63: 3
...
